2025-06-08 21:30:26,888 - INFO - Configuração carregada de config.yaml
2025-06-08 21:30:26,891 - INFO - Assets path configured: C:\GitHub\SentinelaAI\assets
2025-06-08 21:30:26,895 - INFO - Starting up TCP server on localhost:56295
2025-06-08 21:30:26,907 - INFO - Flet app has started...
2025-06-08 21:30:26,911 - INFO - App URL: tcp://localhost:56295
2025-06-08 21:30:26,911 - INFO - Starting Flet View app...
2025-06-08 21:30:26,913 - INFO - Looking for Flet executable at: C:\Users\nicol\AppData\Local\Programs\Python\Python313\Lib\site-packages\flet_desktop\app\flet\flet.exe
2025-06-08 21:30:26,913 - INFO - Flet View found in: C:\Users\nicol\AppData\Local\Programs\Python\Python313\Lib\site-packages\flet_desktop\app\flet\flet.exe
2025-06-08 21:30:27,306 - INFO - App session started
2025-06-08 21:30:27,319 - INFO - --- INICIANDO CICLO DE ANÁLISE ---
2025-06-08 21:30:27,320 - WARNING - Arquivo de dados 'meus_dados_arduino_historico.csv' não encontrado. Criando um vazio.
2025-06-08 21:30:27,336 - INFO - Arquivo de dados está vazio.
2025-06-08 21:30:27,336 - WARNING - Análise abortada: não foi possível carregar dados ou o arquivo está vazio.
2025-06-08 21:30:38,405 - ERROR - Exception in callback BaseEventLoop.run_in_executor()
handle: <Handle BaseEventLoop.run_in_executor()>
Traceback (most recent call last):
  File "C:\Users\nicol\AppData\Local\Programs\Python\Python313\Lib\asyncio\events.py", line 89, in _run
    self._context.run(self._callback, *self._args)
    ~~~~~~~~~~~~~~~~~^^^^^^^^^^^^^^^^^^^^^^^^^^^^^
  File "C:\Users\nicol\AppData\Local\Programs\Python\Python313\Lib\asyncio\base_events.py", line 901, in run_in_executor
    executor.submit(func, *args), loop=self)
    ~~~~~~~~~~~~~~~^^^^^^^^^^^^^
  File "C:\Users\nicol\AppData\Local\Programs\Python\Python313\Lib\concurrent\futures\thread.py", line 171, in submit
    raise RuntimeError('cannot schedule new futures after shutdown')
RuntimeError: cannot schedule new futures after shutdown
